Traceback (most recent call last):
  File "/Users/sbhardwa/opt/miniconda3/envs/jupyterbook/lib/python3.10/site-packages/jupyter_cache/executors/utils.py", line 51, in single_nb_execution
    executenb(
  File "/Users/sbhardwa/opt/miniconda3/envs/jupyterbook/lib/python3.10/site-packages/nbclient/client.py", line 1204, in execute
    return NotebookClient(nb=nb, resources=resources, km=km, **kwargs).execute()
  File "/Users/sbhardwa/opt/miniconda3/envs/jupyterbook/lib/python3.10/site-packages/nbclient/util.py", line 84, in wrapped
    return just_run(coro(*args, **kwargs))
  File "/Users/sbhardwa/opt/miniconda3/envs/jupyterbook/lib/python3.10/site-packages/nbclient/util.py", line 62, in just_run
    return loop.run_until_complete(coro)
  File "/Users/sbhardwa/opt/miniconda3/envs/jupyterbook/lib/python3.10/asyncio/base_events.py", line 646, in run_until_complete
    return future.result()
  File "/Users/sbhardwa/opt/miniconda3/envs/jupyterbook/lib/python3.10/site-packages/nbclient/client.py", line 663, in async_execute
    await self.async_execute_cell(
  File "/Users/sbhardwa/opt/miniconda3/envs/jupyterbook/lib/python3.10/site-packages/nbclient/client.py", line 965, in async_execute_cell
    await self._check_raise_for_error(cell, cell_index, exec_reply)
  File "/Users/sbhardwa/opt/miniconda3/envs/jupyterbook/lib/python3.10/site-packages/nbclient/client.py", line 862, in _check_raise_for_error
    raise CellExecutionError.from_cell_and_msg(cell, exec_reply_content)
nbclient.exceptions.CellExecutionError: An error occurred while executing the following cell:
------------------
from IPython.display import Image, display
import datetime as dt
import pandas as pd
import matplotlib.pyplot as plt
from matplotlib.patches import Patch
import numpy as np
import plotly.express as px
import plotly.figure_factory as ff

df = [dict(Task="Third Year Review", Start='2022-11-01', Finish='2022-12-01'),
      dict(Task="HPC IO tuner", Start='2022-07-10', Finish='2022-07-30'),
      dict(Task="Threads utilisation", Start='2022-06-25', Finish='2022-06-30'),
      dict(Task="Add fenicsX", Start='2022-06-25', Finish='2022-06-30'),
      dict(Task="Second Year Review", Start='2021-11-01', Finish='2021-12-01'),
      dict(Task="CIUK 21", Start='2021-10-01', Finish='2021-11-01'),
      dict(Task="First Year Review", Start='2021-1-01', Finish='2021-2-01')]

fig = ff.create_gantt(df) 
fig.update_layout(
    autosize=False,
    margin=dict(l=20, r=20, t=20, b=20),)
fig.add_vrect(x0="2022-08-1", x1="2022-08-10", 
              annotation_text="SC22 deadline", annotation_position="top left",
              fillcolor="green", opacity=0.25, line_width=0)
fig.layout.title = None

fig.show()
------------------

[0;31m---------------------------------------------------------------------------[0m
[0;31mModuleNotFoundError[0m                       Traceback (most recent call last)
Input [0;32mIn [1][0m, in [0;36m<cell line: 3>[0;34m()[0m
[1;32m      1[0m [38;5;28;01mfrom[39;00m [38;5;21;01mIPython[39;00m[38;5;21;01m.[39;00m[38;5;21;01mdisplay[39;00m [38;5;28;01mimport[39;00m Image, display
[1;32m      2[0m [38;5;28;01mimport[39;00m [38;5;21;01mdatetime[39;00m [38;5;28;01mas[39;00m [38;5;21;01mdt[39;00m
[0;32m----> 3[0m [38;5;28;01mimport[39;00m [38;5;21;01mpandas[39;00m [38;5;28;01mas[39;00m [38;5;21;01mpd[39;00m
[1;32m      4[0m [38;5;28;01mimport[39;00m [38;5;21;01mmatplotlib[39;00m[38;5;21;01m.[39;00m[38;5;21;01mpyplot[39;00m [38;5;28;01mas[39;00m [38;5;21;01mplt[39;00m
[1;32m      5[0m [38;5;28;01mfrom[39;00m [38;5;21;01mmatplotlib[39;00m[38;5;21;01m.[39;00m[38;5;21;01mpatches[39;00m [38;5;28;01mimport[39;00m Patch

[0;31mModuleNotFoundError[0m: No module named 'pandas'
ModuleNotFoundError: No module named 'pandas'

